Workbook
Name DATA17: #REF!
Name DATA18: #REF!
Name DATA19: #REF!
Name DATA20: #REF!
Name DATA21: #REF!
Name DATA22: #REF!
Name DATA23: #REF!
Name DATA24: #REF!
Name DATA25: #REF!

Sheet TUTORIAL
J1: Rotary Maintenance Department | AK1: No. | AM1: : | AN1: FRM-MRT-4115 | BG1: Rotary Maintenance Department | CH1: No. | CJ1: : | DD1: Rotary Maintenance Department | EE1: No. | EG1: :
AK2: Rev. | AM2: : | AN2: 2 | CH2: Rev. | CJ2: : | EE2: Rev. | EG2: :
J3: SUMMARY OF INSPECTION SHEET | AK3: Date | AM3: : | AN3: Jan 20 2021 | BG3: TUTORIAL ONLINE INSPECTION REPORT | CH3: Date | CJ3: : | CK3: 46073 | DD3: TUTORIAL ONLINE INSPECTION REPORT | EE3: Date | EG3: : | EH3: 46073
AK4: Page | AM4: : | AP4: of | CH4: Page | CJ4: : | CM4: of | EE4: Page | EG4: : | EJ4: of
A5: PLANT: | F5: TAG NO: | N5: EQUIPMENT NAME | X5: PROBLEM TITLE | AD5: ABNORMAL SOUND
A6: CA-1 | F6: PU-1502-A | N6: CHLORINE WATER PUMP | X6: AT REQUEST SLIP | AX6: A. | AY6: PETUNJUK PENGISIAN 'SUMMARY INSPECTION REPORT' | CU6: B. | CV6: PETUNJUK PENYIMPANAN DAN ALUR APPROVAL/REVISION
A7: DATE OF REPAIR | N7: 29-02-2060 | X7: REPAIR HOUR | AD7: 8 H | AK7: MAN HOUR | AP7: 24 H | AY7: 1. | AZ7: Area yang di-highlight kuning boleh diisi dengan tulisan free-text sesuai contoh | CV7: 1. | CW7: Buka file 'Inspection Report Online Template (Read Only)' di Box\TEMPORARY\000 Online Inspection Report (Trial)
A8: INSPECTOR (person) | N8: RAMA, HAVIT, 2 MPS | AK8: Prsn x Repair Hrs | AY8: 2. | AZ8: Bagian yang biru harus diisi mengikuti drop down list | CV8: 2. | CW8: Klik 'File' kemudian 'Save As', simpan file di folder masing-masing.
A9: PHENOMENA (what happen) | N9: 1. | O9: HIGH VIBRATION | Y9: =IF(Z9="","", "4.") | AJ9: Notes: | AY9: 3. | AZ9: Jika ada item yang tidak tercantum di list, mohon diinformasikan ke PIC Report per Plant (akan didiskusikan untuk penambahan list) | CV9: 3. | CW9: Isi Summary Inspection Report sesuai petunjuk di bagian A
N10: =IF(O10="","", "2.") -> 2. | O10: BEARING ABN SOUND | Y10: =IF(Z10="","", "5.") | AJ10: COUPLING BROKEN = RUBBER | AY10: 4. | AZ10: Jika perlu mencantumkan detail informasi lainnya, dapat diisi di bagian "Notes:" | CV10: 4. | CW10: Jika sudah lengkap, Klik 'Ctrl + P' kemudian atur settingan sesuai gambar berikut:
N11: =IF(O11="","", "3.") -> 3. | O11: COUPLING BROKEN | Y11: =IF(Z11="","", "6.") | AY11: 5. | AZ11: Bagian 'PHENOMENA' diisi dengan "Type of Equiment / Part of Equipment + Phenomena" | CW11: - | CX11: Printer = 'Microsoft Print to PDF'
A12: CONTENT (kind of inspection) | N12: =IF(O12="","", "1.") -> 1. | O12: BEARING | V12: =IF(O12="","", ":") -> : | W12: REPLACE | AB12: =IF(AC12="","", ";") | AJ12: Notes: | AZ12: Jika ada temuan yg non-reguler = pilih "Others:", lalu tambahkan deskripsi di "Notes" | CW12: - | CX12: Setting = 'Print Entire Workbook'
N13: =IF(O13="","", "2.") -> 2. | O13: MECHANICAL SEAL | V13: =IF(O13="","", ":") -> : | W13: REPLACE | AB13: =IF(AC13="","", ";") | AJ13: RUBBER COUPLING NEW = 2 PCS | AY13: 6. | AZ13: Bagian 'CONTENT' diisi dengan "Part of Equipment / Detail of Part + Kind of Inspection or Maintenance Activity" | CW13: - | CX13: Pages = 2-4 (default jika report lengkap); sesuaikan dengan kebutuhan
N14: =IF(O14="","", "3.") -> 3. | O14: RUBBER COUPLING | V14: =IF(O14="","", ":") -> : | W14: REPLACE | AB14: =IF(AC14="","", ";") | AJ14: EX-USE PU-1503-A = 2 PCS | AZ14: Detail informasi dapat ditambahkan di "Notes" (seperti contoh) | CW14: Lalu Klik 'PRINT'
N15: =IF(O15="","", "4.") | V15: =IF(O15="","", ":") | AB15: =IF(W15="","", ";") | AY15: 7. | AZ15: Bagian 'CAUSE' diisi dengan sesuai list 'Direct Cause' dan 'Root Cause' | CV15: 5. | CW15: Berikan nama file sesuai format berikut:
N16: =IF(O16="","", "5.") | V16: =IF(O16="","", ":") | AB16: =IF(W16="","", ";") | AZ16: Direct Cause = Kenapa 'PHENOMENA' terjadi ? (pada contoh, 'Kenapa High Vibration dan Bearing Abnormal Sound', karena 'BEARING DAMAGE (OIL CONTAMINATION))' | CW16: TAG.NO_TANGGAL-ACTION_PROBLEM_NAMA
A17: CAUSE (why this happened) | N17: Direct Cause: | R17: Machine (ME): | AF17: Root Cause : | AJ17: Bad Prevention (BV): | CW17: Contoh:
N18: 1. BEARING DAMAGE (OIL CONTAMINATION) 2. RUBBER COUPLING DAMAGE | AF18: 1. NO WATER SPLASHER INSTALLED 2. COUPLING MISALIGNMENT | AZ18: Root Cause = Kenapa 'Direct Cause' bisa terjadi ? (pada contoh, 'Kenapa 'BEARING DAMAGE (OIL CONTAMINATION)', karena 'NO WATER SPLASHER INSTALLED' sehingga air masuk ke oil chamber) | CW18: PU-1502-B_20260220_ABNORMAL SOUND_RAMA
CV19: 6. | CW19: Simpan File di lokasi folder plant masing-masing.
A20: Next Action (how to solve it) | N20: Next Action + Part of Equipment / Detail of Part + additional notes (optional) | AY20: 8. | AZ20: Bagian 'Next Action' diisi dengan follow up action yang perlu dilakukan di next overhaul (format harus sesuai panduan) | CW20: Contoh: CA-Plant
N21: 1. REPLACE RUBBER COUPLING IF SPAREPART READY 2. REBUSHING / COATING SHAFT IN OIL SEAL POSITION (IN THIS REPAIR = ONLY MOVE POSITION) 2. REBUSHING BEARING HOUSING (ALREADY REACH THE MAX TOLERANCE LIMIT) | AY21: 9. | AZ21: Bagian 'Counter measure' diisi dengan aksi yang telah dilakukan untuk mencegah 'Root Cause' terjadi lagi (format harus sesuai panduan) | CW21: Box\TEMPORARY\000 Online Inspection Report (Trial)\CA Plant\1. Report Teknisi (initial and Revised)
AY22: 10. | AZ22: Bagian 'RECOMMENDATION' diisi dengan ide improvement yang dapat dilakukan untuk meningkatkan kualitas mesin | CV22: 7. | CW22: Report dari Teknisi akan di-check oleh Staff PIC per plant.
AY23: 11. | AZ23: Bagian 'RESULT OF TEST RUN' diisi sesuai hasil test-run (lihat lampiran) | CW23: - | CX23: Jika Approved akan disimpan di '2. Approved by Staff'
A24: Counter measure (How to prevent it) | N24: Countermeasure Action + Part of Equipment / Detail of Part + additional notes (optional) | AZ24: Khusus untuk bagian 'Vibration Result', mengikuti standard common centrifugal pump. Untuk special equipment, silakan konfirmasi ke tim monitoring | CW24: - | CX24: Jika perlu revisi akan disimpan di folder '4. Need to be Revised'
N25: INSTALL WATER SPLASHER | CV25: 8. | CW25: Staff bertanggung jawab untuk melakukan follow-up ke Section Chief terkait report yang sudah 'approved by staff'
AY26: 12. | AZ26: Bagian 'REMARKS' diisi data full close (penting untuk analisa performa)
A27: RECOMMENDATION (what is your idea to improve this machine) | N27: CHANGE MECHANICAL SEAL TYPE TO EXTERNAL MOUNTING (MORE RELIABLE) TO PREVENT FREQUENT LEAK | AZ27: Jika ada hal lain yang perlu diinformasikan, tulis di 'Other Remarks' | CV27: 9. | CW27: Section Chief akan melakukan review final untuk report tersebut.
AY28: 13. | AZ28: Bagian 'REPLACEMENT PARTS' diisi dengan part-part yang diganti, tuliskan detail spesifikasi dan/atau materialnya (semakin detail lebih bagus) | CW28: - | CX28: Jika Approved akan disimpan di Folder '3. Approved by SC'
A29: RESULT | F29: DATE | K29: ATTENDS NAME | S29: PROCESS : | W29: OWEN | AE29: ROTARY: | AH29: HAVIT | CW29: - | CX29: Jika perlu revisi akan disimpan di folder '4. Need to be Revised'
A30: OF | F30: 58501 | K30: PRESSURE | S30: 3,1 | W30: kg/cm2 | AE30: VIBRATION | AM30: NOISE | AY30: 14. | AZ30: Bagian 'NOTES' dapat digunakan untuk mencantumkan informasi lain. | CV30: 10. | CW30: Report yang sudah ada di folder 'Approved by SC' akan dipindahkan oleh Admin (Pak Rizki) ke ASC EDB
A31: TEST RUN | K31: FLOW RATE | S31: - | W31: m3/hr | Y31: EQUIPMENT | AE31: GOOD | AM31: GOOD | AY31: 15. | AZ31: Jangan lupa untuk menuliskan nama penulis di bagian 'WRITTEN' untuk approval report
K32: MOTOR CURRENT | S32: 12 | W32: A | Y32: MOTOR | AE32: GOOD | AM32: GOOD
A33: Task Category: | F33: Vibration result : | M33: CS | U33: ACS | AC33: DE | AK33: NDE | AQ33: Specific for centrifugal pump (ISO-10816-7). for others, please confirm Monitoring team | AY33: 16. | AZ33: Report yang memerlukan 'Detail Inspection Report' untuk Centrifugal Pump dapat diisi di sheet-3 | CU33: C. | CV33: LAMPIRAN
A34: BM | F34: =IF(MAX(M35:R35,U35:Z35,AC35:AH35,AK35:AP35)<=2.5,"A - Newly Commissioned Machine", IF(MAX(M35:R35,U35:Z35,AC35:AH35,AK35:AP35)<=4,"B - Unrestricted Long-term Op.", IF(MAX(M35:R35,U35:Z35,AC35:AH35,AK35:AP35)<=6.5,"C - Restricted Long-term Op.", "D - Risk Causing Damage"))) -> D - Risk Causing Damage | K34: T | M34: V | O34: H | Q34: A | S34: T | U34: V | W34: H | Y34: A | AA34: T | AC34: V | AE34: H | AG34: A | AI34: T | AK34: V | AM34: H | AO34: A | CV34: - | CW34: Vibration Severity Chart per ISO 10816-7
K35: 60 | M35: 0.1 | O35: 3 | Q35: 0.2 | S35: 60 | U35: 0.4 | W35: 0.1 | Y35: 7 | AA35: 60 | AC35: 0.1 | AE35: 0.1 | AG35: 0.3 | AI35: 60 | AK35: 0.5 | AM35: 5 | AO35: 0.2 | AY35: 17. | AZ35: Report yang memerlukan 'Check Point List (CPL)' equipment lain, dokumennya dapat diminta ke Staff terkait. | CV35: - | CW35: Please use Category 1 for our reports
A36: REMARKS | F36: FULL CLOSE DATA: | U36: Other Remarks: | AY36: 18. | AZ36: Lampirankan dokumentasi Inspeksi di sheet-4
F37: PRESSURE | M37: 4 | Q37: kg/cm2
F38: MOTOR CURRENT | M38: 8 | Q38: A
A39: REPLACEMENT PARTS
A40: NO | D40: PARTS NAME | P40: QTY | S40: MODIFY | W40: NEW TYPE / MATERIAL | AN40: REMARK
...

Sheet ISI DATA
A2: NAMA | B2: PLANT | C2: TAG NO | D2: EQUIPMENT NAME | E2: PROBLEM TITLE AT REQUEST SLIP | F2: MRS No. | G2: DATE OF REPAIR START | H2: DATE OF REPAIR FINISH | I2: REPAIR HOUR | J2: INSPECTOR (Person) | K2: INSPECTOR (Name) | L2: MAN HOUR (Person Repair Hour) | M2: PHENOMENA (What happen) | N2: PHENOMENA (Note) | O2: CONTENT - PART (Kind of inspection) | P2: CONTENT - ACTION (Kind of inspection) | Q2: CONTENT - NOTE (Kind of inspection) | R2: CAUSE - DIRECT CAUSE (Why this happened) | S2: DETAIL CAUSE | T2: CAUSE - ROOT CAUSE (Why this happened) | U2: DETAIL ROOT CAUSE | V2: NET ACTION (How to solve it) | W2: COUNTER MEASURE (How to prevent it) | X2: RECOMMENDATION (What is your idea to improve this machine) | Y2: REPLACEMENT PARTS NUMBER | Z2: REPLACEMENT PARTS NAME | AA2: REPLACEMENT PARTS QTY | AB2: REPLACEMENT PARTS MODIFY | AC2: REPLACEMENT PARTS MATERIAL | AD2: REPLACEMENT PARTS REMARK | AF2: RESULT OF TEST RUN DATE | AG2: ATTENDS NAME PROCESS | AH2: ATTENDS NAME ROTARY | AI2: PRESSURE | AJ2: FLOW RATE | AK2: MOTOR CURRENT | AL2: EQUIPMENT (VIBRATION) | AM2: EQUIPMENT (NOISE) | AN2: MOTOR (VIBRATION) | AO2: MOTOR (NOISE) | AP2: TASK CATEGORY | AQ2: VIBRATION RESULT | AR2: CS (VIBRATION - VERTICAL) | AS2: CS (VIBRATION - HORIZONTAL) | AT2: CS (VIBRATION - AXIAL) | AU2: ACS (VIBRATION - VERTICAL) | AV2: ACS (VIBRATION - HORIZONTAL) | AW2: ACS (VIBRATION - AXIAL) | AX2: DE (VIBRATION - VERTICAL) | AY2: DE (VIBRATION - HORIZONTAL) | AZ2: DE (VIBRATION - AXIAL) | BA2: NDE (VIBRATION - VERTICAL) | BB2: NDE (VIBRATION - HORIZONTAL) | BC2: NDE (VIBRATION - AXIAL) | BD2: CS (TEMPERATURE) | BE2: ACS (TEMPERATURE) | BF2: DE (TEMPERATURE) | BG2: NDE (TEMPERATURE) | BH2: REMARK TEST RUN | BI2: TEST RUN FULL CLOSE (Centrifugal Pump) PRESSURE | BJ2: TEST RUN FULL CLOSE (Centrifugal Pump) MOTOR CURRENT
L3: =I3*J3 -> 0 | AF3: =H3 -> 0 | AQ3: =IF(OR(MAX(AR3:BC3)=0, MAX(AR3:BC3)=""), "", IF(MAX(AR3:BC3)>=7.1, "Damage Occour", IF(MAX(AR3:BC3)>=4.5, "Restricted Operation", IF(MAX(AR3:BC3)>=2.3, "Unrestricted Operation", IF(MAX(AR3:BC3)>=0.1, "EXCELLENT", "")))))

Sheet AUTO DARI ISI DATA
J1: Rotary Maintenance Department | AK1: No. | AM1: : | AN1: FRM-MRT-4115
AK2: Rev. | AM2: : | AN2: 3
J3: SUMMARY OF INSPECTION SHEET | AK3: Date | AM3: : | AN3: June 25, 2026
AK4: Page | AM4: : | AP4: of
A5: PLANT | E5: TAG NO | J5: EQUIPMENT NAME | N5: ='ISI DATA'!D3 -> 0 | V5: PROBLEM TITLE AT REQUEST SLIP | AA5: ='ISI DATA'!E3 -> 0 | AO5: MRS No.
A6: ='ISI DATA'!B3 -> 0 | E6: ='ISI DATA'!C3 -> 0 | AO6: ='ISI DATA'!F3 -> 0
A7: DATE OF REPAIR | J7: START | N7: ='ISI DATA'!G3 -> 0 | V7: REPAIR HOUR | AA7: ='ISI DATA'!I3 -> 0 | AI7: MAN HOUR | AO7: ='ISI DATA'!L3 -> 0
J8: FINISH | N8: ='ISI DATA'!H3 -> 0 | AI8: (Person x Repair Hour)
A9: INSPECTOR (Person) | N9: ='ISI DATA'!J3 -> 0
N10: Farhan + 1 MP
A11: PHENOMENA (What happen) | O11: =IF('ISI DATA'!M3="", "", IF('ISI DATA'!M3=0, "", 'ISI DATA'!M3)) | Z11: =IF('ISI DATA'!M6="", "", IF('ISI DATA'!M6=0, "", 'ISI DATA'!M6)) | AL11: Note:
O12: =IF('ISI DATA'!M4="", "", IF('ISI DATA'!M4=0, "", 'ISI DATA'!M4)) | Z12: =IF('ISI DATA'!M7="", "", IF('ISI DATA'!M7=0, "", 'ISI DATA'!M7)) | AL12: =IF('ISI DATA'!N3="", "", IF('ISI DATA'!N3=0, "", 'ISI DATA'!N3))
O13: =IF('ISI DATA'!M5="", "", IF('ISI DATA'!M5=0, "", 'ISI DATA'!M5)) | Z13: =IF('ISI DATA'!M8="", "", IF('ISI DATA'!M8=0, "", 'ISI DATA'!M8))
A14: CONTENT (Kind of inspection) | N14: Part: | P14: =IF('ISI DATA'!O3="", "", IF('ISI DATA'!O3=0, "", 'ISI DATA'!O3)) | Y14: Action: | AA14: =IF('ISI DATA'!P3=0, "", 'ISI DATA'!P3) | AL14: Note:
P15: =IF('ISI DATA'!O4="", "", IF('ISI DATA'!O4=0, "", 'ISI DATA'!O4)) | AA15: =IF('ISI DATA'!P4=0, "", 'ISI DATA'!P4) | AL15: =IF('ISI DATA'!Q3="", "", IF('ISI DATA'!Q3=0, "", 'ISI DATA'!Q3))
P16: =IF('ISI DATA'!O5="", "", IF('ISI DATA'!O5=0, "", 'ISI DATA'!O5)) | AA16: =IF('ISI DATA'!P5=0, "", 'ISI DATA'!P5)
P17: =IF('ISI DATA'!O6="", "", IF('ISI DATA'!O6=0, "", 'ISI DATA'!O6)) | AA17: =IF('ISI DATA'!P6=0, "", 'ISI DATA'!P6)
A18: CAUSE (Why this happened) | N18: Direct Cause | AC18: Root Cause
N23: Detail Cause: | AC23: Detail Cause:
N24: =IF('ISI DATA'!S3="", "", IF('ISI DATA'!S3=0, "", 'ISI DATA'!S3)) | AC24: =IF('ISI DATA'!AN3="", "", IF('ISI DATA'!AN3=0, "", 'ISI DATA'!AN3))
A26: NEXT ACTION (How to solve it) | N26: =IF('ISI DATA'!V3="", "", IF('ISI DATA'!V3=0, "", 'ISI DATA'!V3))
A28: COUNTER MEASURE (How to prevent it) | N28: =IF('ISI DATA'!W3="", "", IF('ISI DATA'!W3=0, "", 'ISI DATA'!W3))
A30: RECOMMENDATION (What is your idea to improve this machine) | N30: =IF('ISI DATA'!X3="", "", IF('ISI DATA'!X3=0, "", 'ISI DATA'!X3))
F32: DATE | K32: ATTENDS NAME | S32: PROCESS : | W32: =IF('ISI DATA'!AG3="", "", IF('ISI DATA'!AG3=0, "", 'ISI DATA'!AG3)) | AB32: ROTARY : | AF32: =IF('ISI DATA'!AH3="", "", IF('ISI DATA'!AH3=0, "", 'ISI DATA'!AH3))
B33: RESULT OF TEST RUN | F33: ='ISI DATA'!AF3 -> 0 | K33: PRESSURE | S33: ='ISI DATA'!AI3 -> 0 | W33: kg/cm2 | AE33: VIBRATION | AN33: NOISE
K34: FLOW RATE | S34: ='ISI DATA'!AJ3 -> 0 | W34: m3/hr | Y34: EQUIPMENT | AE34: ='ISI DATA'!AL3 -> 0 | AN34: ='ISI DATA'!AM3 -> 0
K35: MOTOR CURRENT | S35: ='ISI DATA'!AK3 -> 0 | W35: A | Y35: MOTOR | AE35: ='ISI DATA'!AN3 -> 0 | AN35: ='ISI DATA'!AO3 -> 0
A36: TASK CATEGORY | F36: Vibration result : | K36: CS | S36: ACS | AA36: DE | AI36: NDE | AQ36: Specific for centrifugal pump (ISO-10816-7). for others, please confirm Monitoring team
A37: =IF('ISI DATA'!AP3="", "", IF('ISI DATA'!AP3=0, "", 'ISI DATA'!AP3)) | F37: ='ISI DATA'!AQ3 | K37: T | M37: V | O37: H | Q37: A | S37: T | U37: V | W37: H | Y37: A | AA37: T | AC37: V | AE37: H | AG37: A | AI37: T | AK37: V | AM37: H | AO37: A
K38: ='ISI DATA'!BD3 -> 0 | M38: ='ISI DATA'!AR3 -> 0 | O38: ='ISI DATA'!AS3 -> 0 | Q38: ='ISI DATA'!AT3 -> 0 | S38: ='ISI DATA'!BE3 -> 0 | U38: ='ISI DATA'!AU3 -> 0 | W38: ='ISI DATA'!AV3 -> 0 | Y38: ='ISI DATA'!AW3 -> 0 | AA38: ='ISI DATA'!BF3 -> 0 | AC38: ='ISI DATA'!AX3 -> 0 | AE38: ='ISI DATA'!AY3 -> 0 | AG38: ='ISI DATA'!AZ3 -> 0 | AI38: ='ISI DATA'!BG3 -> 0 | AK38: ='ISI DATA'!BA3 -> 0 | AM38: ='ISI DATA'!BB3 -> 0 | AO38: ='ISI DATA'!BC3 -> 0
A39: REMARKS | E39: TEST RUN FULL CLOSE (Centrifugal Pump) | Q39: REMARKS
E40: PRESUURE | I40: : | J40: ='ISI DATA'!BI3 -> 0 | Q40: ='ISI DATA'!BH3 -> 0
E41: MOTOR CURRENT | I41: : | J41: ='ISI DATA'!BJ3 -> 0
A42: REPLACEMENT PARTS
A43: NO | D43: PARTS NAME | P43: QTY | S43: MODIFY | W43: NEW TYPE / MATERIAL | AN43: REMARK
S44: Y/N
A45: ='ISI DATA'!Y3 -> 0 | D45: ='ISI DATA'!Z3 -> 0 | P45: ='ISI DATA'!AA3 -> 0 | S45: ='ISI DATA'!AB3 -> 0 | W45: ='ISI DATA'!AC3 -> 0 | AN45: ='ISI DATA'!AD3 -> 0
A46: ='ISI DATA'!Y4 -> 0 | D46: ='ISI DATA'!Z4 -> 0 | P46: ='ISI DATA'!AA4 -> 0 | S46: ='ISI DATA'!AB4 -> 0 | W46: ='ISI DATA'!AC4 -> 0 | AN46: ='ISI DATA'!AD4 -> 0
A47: ='ISI DATA'!Y5 -> 0 | D47: ='ISI DATA'!Z5 -> 0 | P47: ='ISI DATA'!AA5 -> 0 | S47: ='ISI DATA'!AB5 -> 0 | W47: ='ISI DATA'!AC5 -> 0 | AN47: ='ISI DATA'!AD5 -> 0
A48: ='ISI DATA'!Y6 -> 0 | D48: ='ISI DATA'!Z6 -> 0 | P48: ='ISI DATA'!AA6 -> 0 | S48: ='ISI DATA'!AB6 -> 0 | W48: ='ISI DATA'!AC6 -> 0 | AN48: ='ISI DATA'!AD6 -> 0
...

Sheet CPL PUMP
G1: Rotary Maintenance Department | AD1: No. | AF1: : | AG1: CPL - MRT - 4202
G2: Detailed Inspection Sheet | AD2: Rev. | AF2: : | AG2: 2
G3: CENTRIFUGAL PUMP | AD3: Date | AF3: : | AG3: September 08, 2009
AD4: Page | AF4: : | AG4: 1 | AH4: of | AJ4: 1
A5: INSPECTION | G5: VISUAL | K5: CONDITION | O5: UNIT | Y5: UNIT | Z5: STANDARD | AC5: ACTION | AH5: REMARK
A6: ITEM | G6: GOOD | I6: BAD | O6: AFTER | T6: BEFORE
A7: Drive and Bearing | O7: Axial clrnc | T7: Axial clrnc | Y7: mm
A9: Non Drive Bearing | O9: Radial clrnc: | T9: Radial clrnc: | Y9: mm
A11: Impeller | O11: diameter | T11: diameter | Y11: mm
A13: Casing | O13: Gap to impeller | T13: Gap to impeller | Y13: mm
A14: *fill in the gap data if open/semi-open impeller type
A15: Flushing/Quenching
A16: Bearing Housing | O16: ID 0º | T16: ID 0º | Y16: mm
A17: - DE (coupl side) | O17: ID 90º | T17: ID 90º | Y17: mm
A18: - NDE (anti coupl) | O18: ID 0º | T18: ID 0º | Y18: mm
O19: ID 90º | T19: ID 90º | Y19: mm
A20: Mechaseal :
A21: - Mating /Seal Ring
A25: - V-Packing / O-Ring
A27: - Spring & collar
A30: - Bellows
A33: Gland Packing
A34: - Stuffing box
A37: - Lantern ring
A39: Shaft Sleeve | O39: OD: | T39: OD: | Y39: mm
A42: Gland bush | O42: ID: | T42: ID: | Y42: mm
O43: Clearance: | T43: Clearance: | Y43: mm | Z43: General:
Z44: 0.6 mm
A45: Oil seal
A48: Shaft | O48: Run out: | T48: Run out: | Y48: mm
A52: Wear Ring | O52: OD impeller side | T52: OD impeller side
Y53: mm
O54: ID casing side | T54: ID casing side
Y55: mm
A56: V-belts | O56: Tension: | T56: Tension: | Y56: kgf/
Y57: mm
A58: Pulley | O58: Alignment | T58: Alignment | Z58: less than
O59: 9tan (β)), x/y = | T59: 9tan (β)), x/y = | Z59: tan (1/3° (20') )
Z60: =
O61: ……………… | T61: ……………… | Z61: 0.0058
...

Sheet BUKTI FOTO
G1: Rotary Maintenance Department | AB1: No. | AD1: :
G2: INSPECTION PHOTOGRAPH | AB2: Rev. | AD2: :
AB3: Date | AD3: :
AB4: Page | AD4: :
A6: The table below shows the photograph during inspection:
A8: NO | B8: PARTS INSPECTION PHOTOGRAPH | X8: NOTES
A9: 1
A29: 2
A49: 3

Sheet LIST
D2: Action | G2: Cause
A3: Phenomena: | D3: part/equipments | E3: Kind of Inspection/Activity | G3: direct cause | H3: Root cause | J3: STATUS: | L3: VIBRATION | O3: VISUAL | P3: ACTION | R3: Plant | T3: Number
G4: Man (MN): | H4: Bad Prevention (BV): | J4: GOOD | L4: GOOD | O4: ✓ | P4: Replace | R4: CA-1 | T4: 0 | W4: Nama
A5: GENERAL FINDING | B5: ABNORMAL SOUND | D5: AIR FILTER | E5: ADJUST | G5: Material (ML): | H5: Bad Repair (BR): | J5: NOT GOOD | L5: SATISFACTORY | P5: Re-use | R5: CA-2 | T5: 1 | W5: Tag equip | X5: tahun | Y5: bulan | Z5: tanggal | AA5: PROBLEM TITLE AT REQUEST SLIP | AB5: nama
B6: OVER CURRENT TRIP | D6: BASE FRAME | E6: CHECK MEGGER | G6: Machine (ME): | H6: Bad Scheduling (BS): | J6: GOOD/NOT GOOD | L6: UNSATISFACTORY | P6: Recondition | R6: CA-3 | T6: 2
B7: HIGH VIBRATION | D7: BEARING | E7: CLEANING | G7: Method (MD): | H7: Bad Inspection (BI): | L7: UNACCEPTABLE | R7: CA-4 | T7: 3
B8: LOW PERFOMANCE | D8: BEARING MONITOR | E8: PENETRANT TEST | G8: External (EL): | H8: Bad Design (BD): | R8: CA-5 | T8: 4
B9: INTERLOCK TRIP | D9: BELT | E9: RECONDITION | H9: Bad Construction (BC): | R9: PWP | T9: 5
B10: OVERHEAT | D10: BOLT | E10: REFILL | H10: Process Condition (PC): | R10: PVC-1 | T10: 6
B11: PART LIFETIME | D11: CASING | E11: REPAIR | H11: Miss Operation (MO): | R11: PVC-2 | T11: 7
A12: BASE FRAME | B12: BASE FRAME CORROSION | D12: CHAIN | E12: REPLACE | H12: External (EX): | R12: PVC-3 | T12: 8
A13: BEARING | B13: BEARING ABN SOUND | D13: COUPLING | E13: VISUAL INSPECTION | R13: PVC-4 | T13: 9
B14: BEARING HIGH TEMP | D14: COVER | R14: PVC-5 | T14: 10
A15: POWER TRANS - BELT | B15: BELT BROKEN | D15: DIAPHRAGM | R15: UTL | T15: 11
B16: BELT CRACK | D16: DRY GAS SEAL | G16: TASK CAT | I16: Problem CPL Pump | R16: VCM-1 | T16: 12
B17: BELT ABNORMAL NOISE | D17: FLANGE | G17: CBM | I17: Blur | R17: VCM-2 | T17: 13
B18: BELT LOOSE | D18: GASKET CASING | G18: BM | I18: Broken | R18: VCM-3 | T18: 14
B19: PULLEY BROKEN | D19: GLAND PACKING | G19: MDF | I19: Contaminated | T19: 15
B20: PULLEY CORROSIVE | D20: GREASE | G20: TBM | I20: Corrosion | T20: 16
A21: POWER TRANS - COUPLING | B21: COUPLING BROKEN | D21: IMPELLER | G21: CM | I21: Crack | T21: 17
B22: COUPLING ABNORMAL | D22: LABYRINTH SEAL | G22: PM | I22: Cut off | T22: 18
A23: POWER TRANS - CHAIN | B23: CHAIN BROKEN | D23: MECHANICAL SEAL | I23: Damage | T23: 19
B24: CHAIN ABNORMAL | D24: MOTOR | I24: Damage At bearing position | T24: 20
A25: SAFETY COVER | B25: COVER COUPLING BROKEN | D25: OIL | I25: Damage At oil seal seat | T25: 21
B26: COVER ACRYLIC BROKEN | D26: OIL FILTER | I26: Dark | T26: 22
B27: INSULATION BROKEN | D27: OIL SEAL | I27: Dirty | T27: 23
A28: BOLT | B28: BOLT MISSING | D28: OUTER MAGNET | I28: Error | T28: 24
B29: BOLT FRACTURE | D29: PULLEY | I29: Errosion | T29: 25
B30: BOLT LOOSEN | D30: REAR CASING | I30: Hardened | T30: 26
B31: BOLT CORRODED | D31: REFRIGERANT | I31: Jammed | T31: 27
A32: CASING | B32: CASING GASKET LEAK | D32: ROTOR | I32: Overheat | T32: 28
B33: CASING CORROSION | D33: RUBBER COUPLING | I33: Oversize | T33: 29
B34: CASING ERROSION | D34: SHAFT | I34: Pitting | T34: 30
B35: CASING LEAK | D35: SHAFT SLEEVE | I35: Plugging | T35: 31
A36: FLANGE | B36: SUCTION FLANGE LEAK | D36: TUBING/NOZZLE | I36: Scratch | T36: 32
B37: DISHARGE FLANGE LEAK | I37: Worn Out | T37: 33
A38: SHAFT SEAL | B38: GLAND PACKING LEAK | I38: Re-use | T38: 34
B39: MECHANICAL SEAL LEAK | I39: Replace | T39: 35
B40: OIL SEAL LEAK | I40: Good | T40: 36
B41: LABYRINTH SEAL LEAK | I41: Not Good | T41: 37
...
